Workbook

Sheet Three-School Projection
A1: Making Cinderella — Season 1 MBB Revenue: Current / Base / Reach (figures in $000s; estimates)
B2: ST. JOSEPH'S (Hagan 4,200 · A-10) | E2: DAVIDSON (Belk 5,223 · Curry alma mater) | H2: HAWAII (Stan Sheriff 10,300 · Big West)
A3: Revenue line item | B3: Current | C3: Base | D3: Reach | E3: Current | F3: Base | G3: Reach | H3: Current | I3: Base | J3: Reach
A4: Ticketing & game-day
A5: Season ticket sales | B5: 210 | C5: 1200 | D5: 1800 | E5: 270 | F5: 1470 | G5: 2200 | H5: 450 | I5: 2030 | J5: 3000
A6: Single-game & group ticket sales | B6: 120 | C6: 2220 | D6: 3500 | E6: 150 | F6: 2230 | G6: 3500 | H6: 210 | I6: 1630 | J6: 2500
A7: Premium seating (suites, club, courtside) | B7: 40 | C7: 510 | D7: 800 | E7: 80 | F7: 650 | G7: 1000 | H7: 90 | I7: 590 | J7: 900
A8: Postseason ticket (allotment margin — conf/NCAA keep the gate) | B8: 10 | C8: 40 | D8: 60 | E8: 20 | F8: 60 | G8: 80 | H8: 10 | I8: 30 | J8: 50
A9: Concessions (program's share) | B9: 40 | C9: 330 | D9: 500 | E9: 40 | F9: 360 | G9: 550 | H9: 90 | I9: 470 | J9: 700
A10: Parking | B10: 20 | C10: 190 | D10: 300 | E10: 20 | F10: 220 | G10: 350 | H10: 40 | I10: 230 | J10: 350
A11: Game-day novelty / program / merch | B11: 20 | C11: 320 | D11: 500 | E11: 40 | F11: 390 | G11: 600 | H11: 40 | I11: 330 | J11: 500
A12: Subtotal — Ticketing & game-day | B12: =SUM(B5:B11) | C12: =SUM(C5:C11) | D12: =SUM(D5:D11) | E12: =SUM(E5:E11) | F12: =SUM(F5:F11) | G12: =SUM(G5:G11) | H12: =SUM(H5:H11) | I12: =SUM(I5:I11) | J12: =SUM(J5:J11)
A14: Media & broadcasting
A15: Conference media-rights distribution | B15: 450 | C15: 450 | D15: 450 | E15: 450 | F15: 450 | G15: 450 | H15: 250 | I15: 250 | J15: 250
A16: Third-tier / local media (school-retained) | B16: 20 | C16: 160 | D16: 250 | E16: 20 | F16: 190 | G16: 300 | H16: 20 | I16: 130 | J16: 200
A17: School-controlled streaming | B17: 10 | C17: 240 | D17: 400 | E17: 10 | F17: 270 | G17: 450 | H17: 10 | I17: 210 | J17: 350
A18: Radio broadcast rights | B18: 10 | C18: 80 | D18: 120 | E18: 20 | F18: 100 | G18: 150 | H18: 20 | I18: 70 | J18: 100
A19: Subtotal — Media & broadcasting | B19: =SUM(B15:B18) | C19: =SUM(C15:C18) | D19: =SUM(D15:D18) | E19: =SUM(E15:E18) | F19: =SUM(F15:F18) | G19: =SUM(G15:G18) | H19: =SUM(H15:H18) | I19: =SUM(I15:I18) | J19: =SUM(J15:J18)
A21: Conference & NCAA distributions
A22: Conference revenue distribution (non-media share) | B22: 350 | C22: 350 | D22: 350 | E22: 350 | F22: 350 | G22: 350 | H22: 200 | I22: 200 | J22: 200
A23: Conference tournament revenue share | B23: 80 | C23: 80 | D23: 80 | E23: 80 | F23: 80 | G23: 80 | H23: 50 | I23: 50 | J23: 50
A24: NCAA Tournament units / Perf. Fund | B24: 40 | C24: 570 | D24: 700 | E24: 60 | F24: 650 | G24: 800 | H24: 30 | I24: 490 | J24: 600
A25: NCAA broad-based distributions | B25: 210 | C25: 210 | D25: 210 | E25: 210 | F25: 210 | G25: 210 | H25: 190 | I25: 190 | J25: 190
A26: Subtotal — Conference & NCAA distributions | B26: =SUM(B22:B25) | C26: =SUM(C22:C25) | D26: =SUM(D22:D25) | E26: =SUM(E22:E25) | F26: =SUM(F22:F25) | G26: =SUM(G22:G25) | H26: =SUM(H22:H25) | I26: =SUM(I22:I25) | J26: =SUM(J22:J25)
A28: Corporate sponsorship & multimedia rights
A29: Multimedia rights guarantee (Learfield etc.) | B29: 90 | C29: 520 | D29: 800 | E29: 100 | F29: 580 | G29: 900 | H29: 120 | I29: 530 | J29: 800
A30: Corporate / category sponsorships (school) | B30: 80 | C30: 450 | D30: 700 | E30: 90 | F30: 550 | G30: 850 | H30: 100 | I30: 460 | J30: 700
A31: Arena / court naming rights (MBB share) | B31: 20 | C31: 130 | D31: 200 | E31: 20 | F31: 190 | G31: 300 | H31: 30 | I31: 160 | J31: 250
A32: Signage / LED / in-arena advertising | B32: 30 | C32: 190 | D32: 300 | E32: 40 | F32: 230 | G32: 350 | H32: 40 | I32: 200 | J32: 300
A33: Jersey patch (school; national patch = Bkt2) | B33: 0 | C33: 90 | D33: 150 | E33: 0 | F33: 120 | G33: 200 | H33: 0 | I33: 70 | J33: 120
A34: Coach's show / radio show sponsorship | B34: 10 | C34: 90 | D34: 150 | E34: 20 | F34: 120 | G34: 180 | H34: 10 | I34: 80 | J34: 120
A35: Digital & social sponsorship (national = Bkt2) | B35: 10 | C35: 90 | D35: 150 | E35: 10 | F35: 120 | G35: 200 | H35: 10 | I35: 80 | J35: 120
A36: Subtotal — Corporate sponsorship & multimedia rights | B36: =SUM(B29:B35) | C36: =SUM(C29:C35) | D36: =SUM(D29:D35) | E36: =SUM(E29:E35) | F36: =SUM(F29:F35) | G36: =SUM(G29:G35) | H36: =SUM(H29:H35) | I36: =SUM(I29:I35) | J36: =SUM(J29:J35)
A38: Philanthropy & donor
A39: Annual fund / booster donations | B39: 180 | C39: 740 | D39: 1200 | E39: 270 | F39: 1110 | G39: 1800 | H39: 150 | I39: 620 | J39: 1000
A40: Seat-related required donations (PSLs) | B40: 90 | C40: 480 | D40: 800 | E40: 150 | F40: 730 | G40: 1200 | H40: 60 | I40: 410 | J40: 700
A41: Major gifts & endowment (MBB-specific) | B41: 60 | C41: 580 | D41: 1000 | E41: 120 | F41: 880 | G41: 1500 | H41: 40 | I41: 510 | J41: 900
A42: Capital-campaign gifts (facilities) | B42: 30 | C42: 230 | D42: 400 | E42: 60 | F42: 410 | G42: 700 | H42: 30 | I42: 290 | J42: 500
A43: Collective / NIL donor contributions | B43: 90 | C43: 700 | D43: 1200 | E43: 150 | F43: 890 | G43: 1500 | H43: 80 | I43: 590 | J43: 1000
A44: Subtotal — Philanthropy & donor | B44: =SUM(B39:B43) | C44: =SUM(C39:C43) | D44: =SUM(D39:D43) | E44: =SUM(E39:E43) | F44: =SUM(F39:F43) | G44: =SUM(G39:G43) | H44: =SUM(H39:H43) | I44: =SUM(I39:I43) | J44: =SUM(J39:J43)
...

Sheet Bucket 2 (SPV)
A1: Bucket 2 — SPV-only revenue (100% SPV, off the school sheet) ($000s)
A3: Line | B3: Base | C3: Reach
A4: Streaming series (10 hrs @ $1.0M sold / $0.6M cost) | B4: 3200 | C4: 5000 | D4: $400k/hr margin before intl/format
A5: International + format windows | B5: 1500 | C5: 5000 | D5: durable franchise asset; grows w/ library
A6: Live games (3 @ >$1.0M rev / $0.3M cost each) | B6: 2100 | C6: 4000 | D6: school-owned neutral/non-conf games
A7: National presenting sponsor + premium patch | B7: 3000 | C7: 8000 | D7: priced off Netflix eyeballs; SPV IP, not school MMR
A8: MC-originated sponsorship (signage/MMR-scope, ~85% SPV) | B8: 2000 | C8: 6000 | D8: MC sources it, keeps ~85% via originator deal; Learfield ~15%
A9: Content engine / athlete marketing & activation | B9: 500 | C9: 1500 | D9: SPV-produced branded content; players' NIL contracted
A10: Bucket 2 total (SPV) | B10: =SUM(B4:B9) | C10: =SUM(C4:C9)
A12: FULL SPV PICTURE — single season (Bucket 1 share + Bucket 2 − $15M SPV cost)
A13: School | B13: Bkt1 SPV Base | C13: + Bkt2 Base | D13: − SPV cost | E13: =SPV net Base
A14: St. Joseph's | B14: ='Three-School Projection'!E86 | C14: =B10 | D14: -15000 | E14: =B14+C14+D14
A15: Davidson | B15: ='Three-School Projection'!E87 | C15: =B10 | D15: -15000 | E15: =B15+C15+D15
A16: Hawaii | B16: ='Three-School Projection'!E88 | C16: =B10 | D16: -15000 | E16: =B16+C16+D16
A18: School | B18: Bkt1 SPV Reach | C18: + Bkt2 Reach | D18: − SPV cost | E18: =SPV net Reach
A19: St. Joseph's | B19: ='Three-School Projection'!F86 | C19: =C10 | D19: -15000 | E19: =B19+C19+D19
A20: Davidson | B20: ='Three-School Projection'!F87 | C20: =C10 | D20: -15000 | E20: =B20+C20+D20
A21: Hawaii | B21: ='Three-School Projection'!F88 | C21: =C10 | D21: -15000 | E21: =B21+C21+D21
A23: Bucket 2 is 100% SPV and never touches the school sheet or the 80/20 split.
A24: Series & live-game costs are already netted in their lines (EverWonder finances production, recoups cost+10%). The $15M SPV cost = roster/NIL + ops.
A25: MC-originated sponsorship: rather than routing MC-sourced signage/MMR-scope deals through Learfield's fixed guarantee (where the upside gets trapped), MC originates and keeps ~85%. Safer and higher than the 80/20 team-revenue path.
A26: Per-school variance is minor (national platform) — Davidson skews high via the Curry anchor. Reach is the optimistic ceiling; underwrite on Base.
